[2023-06-27T05:47:10.112+0000] {taskinstance.py:1103} INFO - Dependencies all met for dep_context=non-requeueable deps ti=<TaskInstance: bs_customer_invoice_chinnook_dag.load_data_bigquery manual__2023-06-27T05:47:01.645507+00:00 [queued]>
[2023-06-27T05:47:10.118+0000] {taskinstance.py:1103} INFO - Dependencies all met for dep_context=requeueable deps ti=<TaskInstance: bs_customer_invoice_chinnook_dag.load_data_bigquery manual__2023-06-27T05:47:01.645507+00:00 [queued]>
[2023-06-27T05:47:10.118+0000] {taskinstance.py:1308} INFO - Starting attempt 1 of 1
[2023-06-27T05:47:10.125+0000] {taskinstance.py:1327} INFO - Executing <Task(GCSToBigQueryOperator): load_data_bigquery> on 2023-06-27 05:47:01.645507+00:00
[2023-06-27T05:47:10.130+0000] {standard_task_runner.py:57} INFO - Started process 196 to run task
[2023-06-27T05:47:10.133+0000] {standard_task_runner.py:84} INFO - Running: ['***', 'tasks', 'run', 'bs_customer_invoice_chinnook_dag', 'load_data_bigquery', 'manual__2023-06-27T05:47:01.645507+00:00', '--job-id', '63', '--raw', '--subdir', 'DAGS_FOLDER/bs_customer_invoice_chinook_dag.py', '--cfg-path', '/tmp/tmp7ix0_yit']
[2023-06-27T05:47:10.136+0000] {standard_task_runner.py:85} INFO - Job 63: Subtask load_data_bigquery
[2023-06-27T05:47:10.179+0000] {task_command.py:410} INFO - Running <TaskInstance: bs_customer_invoice_chinnook_dag.load_data_bigquery manual__2023-06-27T05:47:01.645507+00:00 [running]> on host 0cd1a7a83c25
[2023-06-27T05:47:10.238+0000] {taskinstance.py:1547} INFO - Exporting env vars: AIRFLOW_CTX_DAG_EMAIL='datokza@gmail.com' AIRFLOW_CTX_DAG_OWNER='okza' AIRFLOW_CTX_DAG_ID='bs_customer_invoice_chinnook_dag' AIRFLOW_CTX_TASK_ID='load_data_bigquery' AIRFLOW_CTX_EXECUTION_DATE='2023-06-27T05:47:01.645507+00:00' AIRFLOW_CTX_TRY_NUMBER='1' AIRFLOW_CTX_DAG_RUN_ID='manual__2023-06-27T05:47:01.645507+00:00'
[2023-06-27T05:47:10.247+0000] {base.py:73} INFO - Using connection ID 'google_cloud_default' for task execution.
[2023-06-27T05:47:10.248+0000] {gcs_to_bigquery.py:372} INFO - Using existing BigQuery table for storing data...
[2023-06-27T05:47:10.292+0000] {gcs_to_bigquery.py:376} INFO - Executing: {'load': {'autodetect': False, 'createDisposition': 'CREATE_IF_NEEDED', 'destinationTable': {'projectId': 'devops-simple', 'datasetId': 'us', 'tableId': 'bs_customer_invoice_chinook'}, 'sourceFormat': 'CSV', 'sourceUris': ['gs://gft-demo-gcs-bucket/extract_transform_customer_invoice_chinook.csv'], 'writeDisposition': 'WRITE_TRUNCATE', 'ignoreUnknownValues': False, 'schema': {'fields': [{'name': 'customer_id', 'type': 'INT64', 'mode': 'REQUIRED'}, {'name': 'full_name', 'type': 'STRING', 'mode': 'NULLABLE'}, {'name': 'company', 'type': 'STRING', 'mode': 'NULLABLE'}, {'name': 'address', 'type': 'STRING', 'mode': 'NULLABLE'}, {'name': 'city', 'type': 'STRING', 'mode': 'NULLABLE'}, {'name': 'state', 'type': 'STRING', 'mode': 'NULLABLE'}, {'name': 'country', 'type': 'STRING', 'mode': 'NULLABLE'}, {'name': 'postal_code', 'type': 'STRING', 'mode': 'NULLABLE'}, {'name': 'phone', 'type': 'STRING', 'mode': 'NULLABLE'}, {'name': 'fax', 'type': 'STRING', 'mode': 'NULLABLE'}, {'name': 'email', 'type': 'STRING', 'mode': 'NULLABLE'}, {'name': 'invoice_id', 'type': 'INT64', 'mode': 'NULLABLE'}, {'name': 'invoice_date', 'type': 'DATE', 'mode': 'NULLABLE'}, {'name': 'billing_address', 'type': 'STRING', 'mode': 'NULLABLE'}, {'name': 'billing_city', 'type': 'STRING', 'mode': 'NULLABLE'}, {'name': 'billing_state', 'type': 'STRING', 'mode': 'NULLABLE'}, {'name': 'billing_country', 'type': 'STRING', 'mode': 'NULLABLE'}, {'name': 'billing_postal_code', 'type': 'STRING', 'mode': 'NULLABLE'}, {'name': 'total', 'type': 'FLOAT64', 'mode': 'NULLABLE'}]}, 'skipLeadingRows': None, 'fieldDelimiter': ',', 'quote': None, 'allowQuotedNewlines': False, 'encoding': 'UTF-8'}}
[2023-06-27T05:47:10.293+0000] {bigquery.py:1562} INFO - Inserting job ***_bs_customer_invoice_chinnook_dag_load_data_bigquery_2023_06_27T05_47_01_645507_00_00_8527071ca0a64c1f4c15236ffc7b935f
[2023-06-27T05:47:11.078+0000] {taskinstance.py:1824} ERROR - Task failed with exception
Traceback (most recent call last):
  File "/home/airflow/.local/lib/python3.7/site-packages/airflow/providers/google/cloud/transfers/gcs_to_bigquery.py", line 377, in execute
    job = self._submit_job(self.hook, job_id)
  File "/home/airflow/.local/lib/python3.7/site-packages/airflow/providers/google/cloud/transfers/gcs_to_bigquery.py", line 306, in _submit_job
    nowait=True,
  File "/home/airflow/.local/lib/python3.7/site-packages/airflow/providers/google/common/hooks/base_google.py", line 468, in inner_wrapper
    return func(self, *args, **kwargs)
  File "/home/airflow/.local/lib/python3.7/site-packages/airflow/providers/google/cloud/hooks/bigquery.py", line 1565, in insert_job
    job._begin()
  File "/home/airflow/.local/lib/python3.7/site-packages/google/cloud/bigquery/job/base.py", line 518, in _begin
    timeout=timeout,
  File "/home/airflow/.local/lib/python3.7/site-packages/google/cloud/bigquery/client.py", line 782, in _call_api
    return call()
  File "/home/airflow/.local/lib/python3.7/site-packages/google/api_core/retry.py", line 288, in retry_wrapped_func
    on_error=on_error,
  File "/home/airflow/.local/lib/python3.7/site-packages/google/api_core/retry.py", line 190, in retry_target
    return target()
  File "/home/airflow/.local/lib/python3.7/site-packages/google/cloud/_http/__init__.py", line 494, in api_request
    raise exceptions.from_http_response(response)
google.api_core.exceptions.NotFound: 404 POST https://bigquery.googleapis.com/bigquery/v2/projects/devops-simple/jobs?prettyPrint=false: Not found: Dataset devops-simple:us
[2023-06-27T05:47:11.103+0000] {taskinstance.py:1350} INFO - Marking task as FAILED. dag_id=bs_customer_invoice_chinnook_dag, task_id=load_data_bigquery, execution_date=20230627T054701, start_date=20230627T054710, end_date=20230627T054711
[2023-06-27T05:47:11.118+0000] {warnings.py:110} WARNING - /home/***/.local/lib/python3.7/site-packages/***/utils/email.py:152: RemovedInAirflow3Warning: Fetching SMTP credentials from configuration variables will be deprecated in a future release. Please set credentials using a connection instead.
  send_mime_email(e_from=mail_from, e_to=recipients, mime_msg=msg, conn_id=conn_id, dryrun=dryrun)

[2023-06-27T05:47:11.119+0000] {configuration.py:676} WARNING - section/key [smtp/smtp_user] not found in config
[2023-06-27T05:47:11.120+0000] {email.py:268} INFO - Email alerting: attempt 1
[2023-06-27T05:47:11.129+0000] {configuration.py:676} WARNING - section/key [smtp/smtp_user] not found in config
[2023-06-27T05:47:11.130+0000] {email.py:268} INFO - Email alerting: attempt 1
[2023-06-27T05:47:11.131+0000] {taskinstance.py:1889} ERROR - Failed to send email to: datokza@gmail.com
Traceback (most recent call last):
  File "/home/airflow/.local/lib/python3.7/site-packages/airflow/models/taskinstance.py", line 1407, in _run_raw_task
    self._execute_task_with_callbacks(context, test_mode)
  File "/home/airflow/.local/lib/python3.7/site-packages/airflow/models/taskinstance.py", line 1558, in _execute_task_with_callbacks
    result = self._execute_task(context, task_orig)
  File "/home/airflow/.local/lib/python3.7/site-packages/airflow/models/taskinstance.py", line 1628, in _execute_task
    result = execute_callable(context=context)
  File "/home/airflow/.local/lib/python3.7/site-packages/airflow/providers/google/cloud/transfers/gcs_to_bigquery.py", line 377, in execute
    job = self._submit_job(self.hook, job_id)
  File "/home/airflow/.local/lib/python3.7/site-packages/airflow/providers/google/cloud/transfers/gcs_to_bigquery.py", line 306, in _submit_job
    nowait=True,
  File "/home/airflow/.local/lib/python3.7/site-packages/airflow/providers/google/common/hooks/base_google.py", line 468, in inner_wrapper
    return func(self, *args, **kwargs)
  File "/home/airflow/.local/lib/python3.7/site-packages/airflow/providers/google/cloud/hooks/bigquery.py", line 1565, in insert_job
    job._begin()
  File "/home/airflow/.local/lib/python3.7/site-packages/google/cloud/bigquery/job/base.py", line 518, in _begin
    timeout=timeout,
  File "/home/airflow/.local/lib/python3.7/site-packages/google/cloud/bigquery/client.py", line 782, in _call_api
    return call()
  File "/home/airflow/.local/lib/python3.7/site-packages/google/api_core/retry.py", line 288, in retry_wrapped_func
    on_error=on_error,
  File "/home/airflow/.local/lib/python3.7/site-packages/google/api_core/retry.py", line 190, in retry_target
    return target()
  File "/home/airflow/.local/lib/python3.7/site-packages/google/cloud/_http/__init__.py", line 494, in api_request
    raise exceptions.from_http_response(response)
google.api_core.exceptions.NotFound: 404 POST https://bigquery.googleapis.com/bigquery/v2/projects/devops-simple/jobs?prettyPrint=false: Not found: Dataset devops-simple:us

During handling of the above exception, another exception occurred:

Traceback (most recent call last):
  File "/home/airflow/.local/lib/python3.7/site-packages/airflow/models/taskinstance.py", line 2295, in email_alert
    send_email(task.email, subject, html_content)
  File "/home/airflow/.local/lib/python3.7/site-packages/airflow/utils/email.py", line 91, in send_email
    **kwargs,
  File "/home/airflow/.local/lib/python3.7/site-packages/airflow/utils/email.py", line 152, in send_email_smtp
    send_mime_email(e_from=mail_from, e_to=recipients, mime_msg=msg, conn_id=conn_id, dryrun=dryrun)
  File "/home/airflow/.local/lib/python3.7/site-packages/airflow/utils/email.py", line 270, in send_mime_email
    smtp_conn = _get_smtp_connection(smtp_host, smtp_port, smtp_timeout, smtp_ssl)
  File "/home/airflow/.local/lib/python3.7/site-packages/airflow/utils/email.py", line 317, in _get_smtp_connection
    else smtplib.SMTP(host=host, port=port, timeout=timeout)
  File "/usr/local/lib/python3.7/smtplib.py", line 251, in __init__
    (code, msg) = self.connect(host, port)
  File "/usr/local/lib/python3.7/smtplib.py", line 336, in connect
    self.sock = self._get_socket(host, port, self.timeout)
  File "/usr/local/lib/python3.7/smtplib.py", line 307, in _get_socket
    self.source_address)
  File "/usr/local/lib/python3.7/socket.py", line 728, in create_connection
    raise err
  File "/usr/local/lib/python3.7/socket.py", line 716, in create_connection
    sock.connect(sa)
OSError: [Errno 99] Cannot assign requested address

During handling of the above exception, another exception occurred:

Traceback (most recent call last):
  File "/home/airflow/.local/lib/python3.7/site-packages/airflow/models/taskinstance.py", line 1887, in handle_failure
    self.email_alert(error, task)
  File "/home/airflow/.local/lib/python3.7/site-packages/airflow/models/taskinstance.py", line 2297, in email_alert
    send_email(task.email, subject, html_content_err)
  File "/home/airflow/.local/lib/python3.7/site-packages/airflow/utils/email.py", line 91, in send_email
    **kwargs,
  File "/home/airflow/.local/lib/python3.7/site-packages/airflow/utils/email.py", line 152, in send_email_smtp
    send_mime_email(e_from=mail_from, e_to=recipients, mime_msg=msg, conn_id=conn_id, dryrun=dryrun)
  File "/home/airflow/.local/lib/python3.7/site-packages/airflow/utils/email.py", line 270, in send_mime_email
    smtp_conn = _get_smtp_connection(smtp_host, smtp_port, smtp_timeout, smtp_ssl)
  File "/home/airflow/.local/lib/python3.7/site-packages/airflow/utils/email.py", line 317, in _get_smtp_connection
    else smtplib.SMTP(host=host, port=port, timeout=timeout)
  File "/usr/local/lib/python3.7/smtplib.py", line 251, in __init__
    (code, msg) = self.connect(host, port)
  File "/usr/local/lib/python3.7/smtplib.py", line 336, in connect
    self.sock = self._get_socket(host, port, self.timeout)
  File "/usr/local/lib/python3.7/smtplib.py", line 307, in _get_socket
    self.source_address)
  File "/usr/local/lib/python3.7/socket.py", line 728, in create_connection
    raise err
  File "/usr/local/lib/python3.7/socket.py", line 716, in create_connection
    sock.connect(sa)
OSError: [Errno 99] Cannot assign requested address
[2023-06-27T05:47:11.145+0000] {standard_task_runner.py:109} ERROR - Failed to execute job 63 for task load_data_bigquery (404 POST https://bigquery.googleapis.com/bigquery/v2/projects/devops-simple/jobs?prettyPrint=false: Not found: Dataset devops-simple:us; 196)
[2023-06-27T05:47:11.178+0000] {local_task_job_runner.py:225} INFO - Task exited with return code 1
[2023-06-27T05:47:11.214+0000] {taskinstance.py:2651} INFO - 0 downstream tasks scheduled from follow-on schedule check
