[2023-06-27T04:14:50.145+0000] {taskinstance.py:1103} INFO - Dependencies all met for dep_context=non-requeueable deps ti=<TaskInstance: bs_customer_invoice_chinnook_dag.store_data_gcs scheduled__2023-06-26T04:00:00+00:00 [queued]>
[2023-06-27T04:14:50.157+0000] {taskinstance.py:1103} INFO - Dependencies all met for dep_context=requeueable deps ti=<TaskInstance: bs_customer_invoice_chinnook_dag.store_data_gcs scheduled__2023-06-26T04:00:00+00:00 [queued]>
[2023-06-27T04:14:50.158+0000] {taskinstance.py:1308} INFO - Starting attempt 1 of 1
[2023-06-27T04:14:50.206+0000] {taskinstance.py:1327} INFO - Executing <Task(LocalFilesystemToGCSOperator): store_data_gcs> on 2023-06-26 04:00:00+00:00
[2023-06-27T04:14:50.219+0000] {standard_task_runner.py:57} INFO - Started process 56 to run task
[2023-06-27T04:14:50.224+0000] {standard_task_runner.py:84} INFO - Running: ['***', 'tasks', 'run', 'bs_customer_invoice_chinnook_dag', 'store_data_gcs', 'scheduled__2023-06-26T04:00:00+00:00', '--job-id', '58', '--raw', '--subdir', 'DAGS_FOLDER/bs_customer_invoice_chinook_dag.py', '--cfg-path', '/tmp/tmprh97fbtx']
[2023-06-27T04:14:50.227+0000] {standard_task_runner.py:85} INFO - Job 58: Subtask store_data_gcs
[2023-06-27T04:14:50.284+0000] {task_command.py:410} INFO - Running <TaskInstance: bs_customer_invoice_chinnook_dag.store_data_gcs scheduled__2023-06-26T04:00:00+00:00 [running]> on host 6d938edef4b8
[2023-06-27T04:14:50.338+0000] {taskinstance.py:1547} INFO - Exporting env vars: AIRFLOW_CTX_DAG_EMAIL='datokza@gmail.com' AIRFLOW_CTX_DAG_OWNER='okza' AIRFLOW_CTX_DAG_ID='bs_customer_invoice_chinnook_dag' AIRFLOW_CTX_TASK_ID='store_data_gcs' AIRFLOW_CTX_EXECUTION_DATE='2023-06-26T04:00:00+00:00' AIRFLOW_CTX_TRY_NUMBER='1' AIRFLOW_CTX_DAG_RUN_ID='scheduled__2023-06-26T04:00:00+00:00'
[2023-06-27T04:14:50.346+0000] {base.py:73} INFO - Using connection ID 'google_cloud_default' for task execution.
[2023-06-27T04:14:52.603+0000] {gcs.py:499} ERROR - Upload attempt of object: extract_transform_customer_invoice_chinook.csv from extract_transform_customer_invoice_chinook.csv has failed. Attempt: 1, max 1.
[2023-06-27T04:14:52.605+0000] {taskinstance.py:1824} ERROR - Task failed with exception
Traceback (most recent call last):
  File "/home/airflow/.local/lib/python3.7/site-packages/google/cloud/storage/blob.py", line 2553, in upload_from_file
    retry=retry,
  File "/home/airflow/.local/lib/python3.7/site-packages/google/cloud/storage/blob.py", line 2368, in _do_upload
    retry=retry,
  File "/home/airflow/.local/lib/python3.7/site-packages/google/cloud/storage/blob.py", line 1891, in _do_multipart_upload
    transport, data, object_metadata, content_type, timeout=timeout
  File "/home/airflow/.local/lib/python3.7/site-packages/google/resumable_media/requests/upload.py", line 154, in transmit
    retriable_request, self._get_status_code, self._retry_strategy
  File "/home/airflow/.local/lib/python3.7/site-packages/google/resumable_media/requests/_request_helpers.py", line 155, in wait_and_retry
    response = func()
  File "/home/airflow/.local/lib/python3.7/site-packages/google/resumable_media/requests/upload.py", line 149, in retriable_request
    self._process_response(result)
  File "/home/airflow/.local/lib/python3.7/site-packages/google/resumable_media/_upload.py", line 114, in _process_response
    _helpers.require_status_code(response, (http.client.OK,), self._get_status_code)
  File "/home/airflow/.local/lib/python3.7/site-packages/google/resumable_media/_helpers.py", line 113, in require_status_code
    *status_codes
google.resumable_media.common.InvalidResponse: ('Request failed with status code', 404, 'Expected one of', <HTTPStatus.OK: 200>)

During handling of the above exception, another exception occurred:

Traceback (most recent call last):
  File "/home/airflow/.local/lib/python3.7/site-packages/airflow/providers/google/cloud/transfers/local_to_gcs.py", line 116, in execute
    gzip=self.gzip,
  File "/home/airflow/.local/lib/python3.7/site-packages/airflow/providers/google/cloud/hooks/gcs.py", line 533, in upload
    partial(blob.upload_from_filename, filename=filename, content_type=mime_type, timeout=timeout)
  File "/home/airflow/.local/lib/python3.7/site-packages/airflow/providers/google/cloud/hooks/gcs.py", line 501, in _call_with_retry
    raise e
  File "/home/airflow/.local/lib/python3.7/site-packages/airflow/providers/google/cloud/hooks/gcs.py", line 490, in _call_with_retry
    f()
  File "/home/airflow/.local/lib/python3.7/site-packages/google/cloud/storage/blob.py", line 2697, in upload_from_filename
    retry=retry,
  File "/home/airflow/.local/lib/python3.7/site-packages/google/cloud/storage/blob.py", line 2557, in upload_from_file
    _raise_from_invalid_response(exc)
  File "/home/airflow/.local/lib/python3.7/site-packages/google/cloud/storage/blob.py", line 4369, in _raise_from_invalid_response
    raise exceptions.from_http_status(response.status_code, message, response=response)
google.api_core.exceptions.NotFound: 404 POST https://storage.googleapis.com/upload/storage/v1/b/blank-space-de-batch/o?uploadType=multipart: {
  "error": {
    "code": 404,
    "message": "The specified bucket does not exist.",
    "errors": [
      {
        "message": "The specified bucket does not exist.",
        "domain": "global",
        "reason": "notFound"
      }
    ]
  }
}
: ('Request failed with status code', 404, 'Expected one of', <HTTPStatus.OK: 200>)
[2023-06-27T04:14:52.626+0000] {taskinstance.py:1350} INFO - Marking task as FAILED. dag_id=bs_customer_invoice_chinnook_dag, task_id=store_data_gcs, execution_date=20230626T040000, start_date=20230627T041450, end_date=20230627T041452
[2023-06-27T04:14:52.640+0000] {warnings.py:110} WARNING - /home/***/.local/lib/python3.7/site-packages/***/utils/email.py:152: RemovedInAirflow3Warning: Fetching SMTP credentials from configuration variables will be deprecated in a future release. Please set credentials using a connection instead.
  send_mime_email(e_from=mail_from, e_to=recipients, mime_msg=msg, conn_id=conn_id, dryrun=dryrun)

[2023-06-27T04:14:52.641+0000] {configuration.py:676} WARNING - section/key [smtp/smtp_user] not found in config
[2023-06-27T04:14:52.641+0000] {email.py:268} INFO - Email alerting: attempt 1
[2023-06-27T04:14:52.649+0000] {configuration.py:676} WARNING - section/key [smtp/smtp_user] not found in config
[2023-06-27T04:14:52.649+0000] {email.py:268} INFO - Email alerting: attempt 1
[2023-06-27T04:14:52.650+0000] {taskinstance.py:1889} ERROR - Failed to send email to: datokza@gmail.com
Traceback (most recent call last):
  File "/home/airflow/.local/lib/python3.7/site-packages/google/cloud/storage/blob.py", line 2553, in upload_from_file
    retry=retry,
  File "/home/airflow/.local/lib/python3.7/site-packages/google/cloud/storage/blob.py", line 2368, in _do_upload
    retry=retry,
  File "/home/airflow/.local/lib/python3.7/site-packages/google/cloud/storage/blob.py", line 1891, in _do_multipart_upload
    transport, data, object_metadata, content_type, timeout=timeout
  File "/home/airflow/.local/lib/python3.7/site-packages/google/resumable_media/requests/upload.py", line 154, in transmit
    retriable_request, self._get_status_code, self._retry_strategy
  File "/home/airflow/.local/lib/python3.7/site-packages/google/resumable_media/requests/_request_helpers.py", line 155, in wait_and_retry
    response = func()
  File "/home/airflow/.local/lib/python3.7/site-packages/google/resumable_media/requests/upload.py", line 149, in retriable_request
    self._process_response(result)
  File "/home/airflow/.local/lib/python3.7/site-packages/google/resumable_media/_upload.py", line 114, in _process_response
    _helpers.require_status_code(response, (http.client.OK,), self._get_status_code)
  File "/home/airflow/.local/lib/python3.7/site-packages/google/resumable_media/_helpers.py", line 113, in require_status_code
    *status_codes
google.resumable_media.common.InvalidResponse: ('Request failed with status code', 404, 'Expected one of', <HTTPStatus.OK: 200>)

During handling of the above exception, another exception occurred:

Traceback (most recent call last):
  File "/home/airflow/.local/lib/python3.7/site-packages/airflow/models/taskinstance.py", line 1407, in _run_raw_task
    self._execute_task_with_callbacks(context, test_mode)
  File "/home/airflow/.local/lib/python3.7/site-packages/airflow/models/taskinstance.py", line 1558, in _execute_task_with_callbacks
    result = self._execute_task(context, task_orig)
  File "/home/airflow/.local/lib/python3.7/site-packages/airflow/models/taskinstance.py", line 1628, in _execute_task
    result = execute_callable(context=context)
  File "/home/airflow/.local/lib/python3.7/site-packages/airflow/providers/google/cloud/transfers/local_to_gcs.py", line 116, in execute
    gzip=self.gzip,
  File "/home/airflow/.local/lib/python3.7/site-packages/airflow/providers/google/cloud/hooks/gcs.py", line 533, in upload
    partial(blob.upload_from_filename, filename=filename, content_type=mime_type, timeout=timeout)
  File "/home/airflow/.local/lib/python3.7/site-packages/airflow/providers/google/cloud/hooks/gcs.py", line 501, in _call_with_retry
    raise e
  File "/home/airflow/.local/lib/python3.7/site-packages/airflow/providers/google/cloud/hooks/gcs.py", line 490, in _call_with_retry
    f()
  File "/home/airflow/.local/lib/python3.7/site-packages/google/cloud/storage/blob.py", line 2697, in upload_from_filename
    retry=retry,
  File "/home/airflow/.local/lib/python3.7/site-packages/google/cloud/storage/blob.py", line 2557, in upload_from_file
    _raise_from_invalid_response(exc)
  File "/home/airflow/.local/lib/python3.7/site-packages/google/cloud/storage/blob.py", line 4369, in _raise_from_invalid_response
    raise exceptions.from_http_status(response.status_code, message, response=response)
google.api_core.exceptions.NotFound: 404 POST https://storage.googleapis.com/upload/storage/v1/b/blank-space-de-batch/o?uploadType=multipart: {
  "error": {
    "code": 404,
    "message": "The specified bucket does not exist.",
    "errors": [
      {
        "message": "The specified bucket does not exist.",
        "domain": "global",
        "reason": "notFound"
      }
    ]
  }
}
: ('Request failed with status code', 404, 'Expected one of', <HTTPStatus.OK: 200>)

During handling of the above exception, another exception occurred:

Traceback (most recent call last):
  File "/home/airflow/.local/lib/python3.7/site-packages/airflow/models/taskinstance.py", line 2295, in email_alert
    send_email(task.email, subject, html_content)
  File "/home/airflow/.local/lib/python3.7/site-packages/airflow/utils/email.py", line 91, in send_email
    **kwargs,
  File "/home/airflow/.local/lib/python3.7/site-packages/airflow/utils/email.py", line 152, in send_email_smtp
    send_mime_email(e_from=mail_from, e_to=recipients, mime_msg=msg, conn_id=conn_id, dryrun=dryrun)
  File "/home/airflow/.local/lib/python3.7/site-packages/airflow/utils/email.py", line 270, in send_mime_email
    smtp_conn = _get_smtp_connection(smtp_host, smtp_port, smtp_timeout, smtp_ssl)
  File "/home/airflow/.local/lib/python3.7/site-packages/airflow/utils/email.py", line 317, in _get_smtp_connection
    else smtplib.SMTP(host=host, port=port, timeout=timeout)
  File "/usr/local/lib/python3.7/smtplib.py", line 251, in __init__
    (code, msg) = self.connect(host, port)
  File "/usr/local/lib/python3.7/smtplib.py", line 336, in connect
    self.sock = self._get_socket(host, port, self.timeout)
  File "/usr/local/lib/python3.7/smtplib.py", line 307, in _get_socket
    self.source_address)
  File "/usr/local/lib/python3.7/socket.py", line 728, in create_connection
    raise err
  File "/usr/local/lib/python3.7/socket.py", line 716, in create_connection
    sock.connect(sa)
OSError: [Errno 99] Cannot assign requested address

During handling of the above exception, another exception occurred:

Traceback (most recent call last):
  File "/home/airflow/.local/lib/python3.7/site-packages/airflow/models/taskinstance.py", line 1887, in handle_failure
    self.email_alert(error, task)
  File "/home/airflow/.local/lib/python3.7/site-packages/airflow/models/taskinstance.py", line 2297, in email_alert
    send_email(task.email, subject, html_content_err)
  File "/home/airflow/.local/lib/python3.7/site-packages/airflow/utils/email.py", line 91, in send_email
    **kwargs,
  File "/home/airflow/.local/lib/python3.7/site-packages/airflow/utils/email.py", line 152, in send_email_smtp
    send_mime_email(e_from=mail_from, e_to=recipients, mime_msg=msg, conn_id=conn_id, dryrun=dryrun)
  File "/home/airflow/.local/lib/python3.7/site-packages/airflow/utils/email.py", line 270, in send_mime_email
    smtp_conn = _get_smtp_connection(smtp_host, smtp_port, smtp_timeout, smtp_ssl)
  File "/home/airflow/.local/lib/python3.7/site-packages/airflow/utils/email.py", line 317, in _get_smtp_connection
    else smtplib.SMTP(host=host, port=port, timeout=timeout)
  File "/usr/local/lib/python3.7/smtplib.py", line 251, in __init__
    (code, msg) = self.connect(host, port)
  File "/usr/local/lib/python3.7/smtplib.py", line 336, in connect
    self.sock = self._get_socket(host, port, self.timeout)
  File "/usr/local/lib/python3.7/smtplib.py", line 307, in _get_socket
    self.source_address)
  File "/usr/local/lib/python3.7/socket.py", line 728, in create_connection
    raise err
  File "/usr/local/lib/python3.7/socket.py", line 716, in create_connection
    sock.connect(sa)
OSError: [Errno 99] Cannot assign requested address
[2023-06-27T04:14:52.661+0000] {standard_task_runner.py:109} ERROR - Failed to execute job 58 for task store_data_gcs (404 POST https://storage.googleapis.com/upload/storage/v1/b/blank-space-de-batch/o?uploadType=multipart: {
  "error": {
    "code": 404,
    "message": "The specified bucket does not exist.",
    "errors": [
      {
        "message": "The specified bucket does not exist.",
        "domain": "global",
        "reason": "notFound"
      }
    ]
  }
}
: ('Request failed with status code', 404, 'Expected one of', <HTTPStatus.OK: 200>); 56)
[2023-06-27T04:14:52.708+0000] {local_task_job_runner.py:225} INFO - Task exited with return code 1
[2023-06-27T04:14:52.756+0000] {taskinstance.py:2651} INFO - 0 downstream tasks scheduled from follow-on schedule check
