[2023-07-26T08:24:37.393+0000] {taskinstance.py:1103} INFO - Dependencies all met for dep_context=non-requeueable deps ti=<TaskInstance: bs_customer_invoice_dag.start_template_job manual__2023-07-26T08:18:23.075973+00:00 [queued]>
[2023-07-26T08:24:37.399+0000] {taskinstance.py:1103} INFO - Dependencies all met for dep_context=requeueable deps ti=<TaskInstance: bs_customer_invoice_dag.start_template_job manual__2023-07-26T08:18:23.075973+00:00 [queued]>
[2023-07-26T08:24:37.400+0000] {taskinstance.py:1308} INFO - Starting attempt 2 of 2
[2023-07-26T08:24:37.407+0000] {taskinstance.py:1327} INFO - Executing <Task(DataflowTemplatedJobStartOperator): start_template_job> on 2023-07-26 08:18:23.075973+00:00
[2023-07-26T08:24:37.412+0000] {standard_task_runner.py:57} INFO - Started process 439 to run task
[2023-07-26T08:24:37.417+0000] {standard_task_runner.py:84} INFO - Running: ['***', 'tasks', 'run', 'bs_customer_invoice_dag', 'start_template_job', 'manual__2023-07-26T08:18:23.075973+00:00', '--job-id', '37', '--raw', '--subdir', 'DAGS_FOLDER/bs_customer_invoice_chinook_dag.py', '--cfg-path', '/tmp/tmpsjsko_ld']
[2023-07-26T08:24:37.419+0000] {standard_task_runner.py:85} INFO - Job 37: Subtask start_template_job
[2023-07-26T08:24:37.458+0000] {task_command.py:410} INFO - Running <TaskInstance: bs_customer_invoice_dag.start_template_job manual__2023-07-26T08:18:23.075973+00:00 [running]> on host 53e9620c1516
[2023-07-26T08:24:37.511+0000] {taskinstance.py:1547} INFO - Exporting env vars: AIRFLOW_CTX_DAG_EMAIL='datokza@gmail.com' AIRFLOW_CTX_DAG_OWNER='okza' AIRFLOW_CTX_DAG_ID='bs_customer_invoice_dag' AIRFLOW_CTX_TASK_ID='start_template_job' AIRFLOW_CTX_EXECUTION_DATE='2023-07-26T08:18:23.075973+00:00' AIRFLOW_CTX_TRY_NUMBER='2' AIRFLOW_CTX_DAG_RUN_ID='manual__2023-07-26T08:18:23.075973+00:00'
[2023-07-26T08:24:37.520+0000] {base.py:73} INFO - Using connection ID 'google_cloud_default' for task execution.
[2023-07-26T08:24:40.582+0000] {taskinstance.py:1824} ERROR - Task failed with exception
Traceback (most recent call last):
  File "/home/airflow/.local/lib/python3.7/site-packages/airflow/providers/google/cloud/operators/dataflow.py", line 675, in execute
    append_job_name=self.append_job_name,
  File "/home/airflow/.local/lib/python3.7/site-packages/airflow/providers/google/cloud/hooks/dataflow.py", line 116, in inner_wrapper
    return func(self, *args, **kwargs)
  File "/home/airflow/.local/lib/python3.7/site-packages/airflow/providers/google/cloud/hooks/dataflow.py", line 116, in inner_wrapper
    return func(self, *args, **kwargs)
  File "/home/airflow/.local/lib/python3.7/site-packages/airflow/providers/google/common/hooks/base_google.py", line 468, in inner_wrapper
    return func(self, *args, **kwargs)
  File "/home/airflow/.local/lib/python3.7/site-packages/airflow/providers/google/cloud/hooks/dataflow.py", line 675, in start_template_dataflow
    response = request.execute(num_retries=self.num_retries)
  File "/home/airflow/.local/lib/python3.7/site-packages/googleapiclient/_helpers.py", line 134, in positional_wrapper
    return wrapped(*args, **kwargs)
  File "/home/airflow/.local/lib/python3.7/site-packages/googleapiclient/http.py", line 915, in execute
    raise HttpError(resp, content, uri=self.uri)
googleapiclient.errors.HttpError: <HttpError 404 when requesting https://dataflow.googleapis.com/v1b3/projects/devops-simple/locations/us-central1/templates:launch?gcsPath=gs%3A%2F%2Fgft-demo-gcs-bucket%2Ftemplate%2Fcustomer_invoice_template&alt=json returned "(fa0487e39ea22a32): Unable to open template file: gs://gft-demo-gcs-bucket/template/customer_invoice_template.". Details: "(fa0487e39ea22a32): Unable to open template file: gs://gft-demo-gcs-bucket/template/customer_invoice_template.">
[2023-07-26T08:24:40.600+0000] {taskinstance.py:1350} INFO - Marking task as FAILED. dag_id=bs_customer_invoice_dag, task_id=start_template_job, execution_date=20230726T081823, start_date=20230726T082437, end_date=20230726T082440
[2023-07-26T08:24:40.610+0000] {warnings.py:110} WARNING - /home/***/.local/lib/python3.7/site-packages/***/utils/email.py:152: RemovedInAirflow3Warning: Fetching SMTP credentials from configuration variables will be deprecated in a future release. Please set credentials using a connection instead.
  send_mime_email(e_from=mail_from, e_to=recipients, mime_msg=msg, conn_id=conn_id, dryrun=dryrun)

[2023-07-26T08:24:40.611+0000] {configuration.py:676} WARNING - section/key [smtp/smtp_user] not found in config
[2023-07-26T08:24:40.611+0000] {email.py:268} INFO - Email alerting: attempt 1
[2023-07-26T08:24:40.618+0000] {configuration.py:676} WARNING - section/key [smtp/smtp_user] not found in config
[2023-07-26T08:24:40.618+0000] {email.py:268} INFO - Email alerting: attempt 1
[2023-07-26T08:24:40.619+0000] {taskinstance.py:1889} ERROR - Failed to send email to: datokza@gmail.com
Traceback (most recent call last):
  File "/home/airflow/.local/lib/python3.7/site-packages/airflow/models/taskinstance.py", line 1407, in _run_raw_task
    self._execute_task_with_callbacks(context, test_mode)
  File "/home/airflow/.local/lib/python3.7/site-packages/airflow/models/taskinstance.py", line 1558, in _execute_task_with_callbacks
    result = self._execute_task(context, task_orig)
  File "/home/airflow/.local/lib/python3.7/site-packages/airflow/models/taskinstance.py", line 1628, in _execute_task
    result = execute_callable(context=context)
  File "/home/airflow/.local/lib/python3.7/site-packages/airflow/providers/google/cloud/operators/dataflow.py", line 675, in execute
    append_job_name=self.append_job_name,
  File "/home/airflow/.local/lib/python3.7/site-packages/airflow/providers/google/cloud/hooks/dataflow.py", line 116, in inner_wrapper
    return func(self, *args, **kwargs)
  File "/home/airflow/.local/lib/python3.7/site-packages/airflow/providers/google/cloud/hooks/dataflow.py", line 116, in inner_wrapper
    return func(self, *args, **kwargs)
  File "/home/airflow/.local/lib/python3.7/site-packages/airflow/providers/google/common/hooks/base_google.py", line 468, in inner_wrapper
    return func(self, *args, **kwargs)
  File "/home/airflow/.local/lib/python3.7/site-packages/airflow/providers/google/cloud/hooks/dataflow.py", line 675, in start_template_dataflow
    response = request.execute(num_retries=self.num_retries)
  File "/home/airflow/.local/lib/python3.7/site-packages/googleapiclient/_helpers.py", line 134, in positional_wrapper
    return wrapped(*args, **kwargs)
  File "/home/airflow/.local/lib/python3.7/site-packages/googleapiclient/http.py", line 915, in execute
    raise HttpError(resp, content, uri=self.uri)
googleapiclient.errors.HttpError: <HttpError 404 when requesting https://dataflow.googleapis.com/v1b3/projects/devops-simple/locations/us-central1/templates:launch?gcsPath=gs%3A%2F%2Fgft-demo-gcs-bucket%2Ftemplate%2Fcustomer_invoice_template&alt=json returned "(fa0487e39ea22a32): Unable to open template file: gs://gft-demo-gcs-bucket/template/customer_invoice_template.". Details: "(fa0487e39ea22a32): Unable to open template file: gs://gft-demo-gcs-bucket/template/customer_invoice_template.">

During handling of the above exception, another exception occurred:

Traceback (most recent call last):
  File "/home/airflow/.local/lib/python3.7/site-packages/airflow/models/taskinstance.py", line 2295, in email_alert
    send_email(task.email, subject, html_content)
  File "/home/airflow/.local/lib/python3.7/site-packages/airflow/utils/email.py", line 91, in send_email
    **kwargs,
  File "/home/airflow/.local/lib/python3.7/site-packages/airflow/utils/email.py", line 152, in send_email_smtp
    send_mime_email(e_from=mail_from, e_to=recipients, mime_msg=msg, conn_id=conn_id, dryrun=dryrun)
  File "/home/airflow/.local/lib/python3.7/site-packages/airflow/utils/email.py", line 270, in send_mime_email
    smtp_conn = _get_smtp_connection(smtp_host, smtp_port, smtp_timeout, smtp_ssl)
  File "/home/airflow/.local/lib/python3.7/site-packages/airflow/utils/email.py", line 317, in _get_smtp_connection
    else smtplib.SMTP(host=host, port=port, timeout=timeout)
  File "/usr/local/lib/python3.7/smtplib.py", line 251, in __init__
    (code, msg) = self.connect(host, port)
  File "/usr/local/lib/python3.7/smtplib.py", line 336, in connect
    self.sock = self._get_socket(host, port, self.timeout)
  File "/usr/local/lib/python3.7/smtplib.py", line 307, in _get_socket
    self.source_address)
  File "/usr/local/lib/python3.7/socket.py", line 728, in create_connection
    raise err
  File "/usr/local/lib/python3.7/socket.py", line 716, in create_connection
    sock.connect(sa)
OSError: [Errno 99] Cannot assign requested address

During handling of the above exception, another exception occurred:

Traceback (most recent call last):
  File "/home/airflow/.local/lib/python3.7/site-packages/airflow/models/taskinstance.py", line 1887, in handle_failure
    self.email_alert(error, task)
  File "/home/airflow/.local/lib/python3.7/site-packages/airflow/models/taskinstance.py", line 2297, in email_alert
    send_email(task.email, subject, html_content_err)
  File "/home/airflow/.local/lib/python3.7/site-packages/airflow/utils/email.py", line 91, in send_email
    **kwargs,
  File "/home/airflow/.local/lib/python3.7/site-packages/airflow/utils/email.py", line 152, in send_email_smtp
    send_mime_email(e_from=mail_from, e_to=recipients, mime_msg=msg, conn_id=conn_id, dryrun=dryrun)
  File "/home/airflow/.local/lib/python3.7/site-packages/airflow/utils/email.py", line 270, in send_mime_email
    smtp_conn = _get_smtp_connection(smtp_host, smtp_port, smtp_timeout, smtp_ssl)
  File "/home/airflow/.local/lib/python3.7/site-packages/airflow/utils/email.py", line 317, in _get_smtp_connection
    else smtplib.SMTP(host=host, port=port, timeout=timeout)
  File "/usr/local/lib/python3.7/smtplib.py", line 251, in __init__
    (code, msg) = self.connect(host, port)
  File "/usr/local/lib/python3.7/smtplib.py", line 336, in connect
    self.sock = self._get_socket(host, port, self.timeout)
  File "/usr/local/lib/python3.7/smtplib.py", line 307, in _get_socket
    self.source_address)
  File "/usr/local/lib/python3.7/socket.py", line 728, in create_connection
    raise err
  File "/usr/local/lib/python3.7/socket.py", line 716, in create_connection
    sock.connect(sa)
OSError: [Errno 99] Cannot assign requested address
[2023-07-26T08:24:40.629+0000] {standard_task_runner.py:109} ERROR - Failed to execute job 37 for task start_template_job (<HttpError 404 when requesting https://dataflow.googleapis.com/v1b3/projects/devops-simple/locations/us-central1/templates:launch?gcsPath=gs%3A%2F%2Fgft-demo-gcs-bucket%2Ftemplate%2Fcustomer_invoice_template&alt=json returned "(fa0487e39ea22a32): Unable to open template file: gs://gft-demo-gcs-bucket/template/customer_invoice_template.". Details: "(fa0487e39ea22a32): Unable to open template file: gs://gft-demo-gcs-bucket/template/customer_invoice_template.">; 439)
[2023-07-26T08:24:40.638+0000] {local_task_job_runner.py:225} INFO - Task exited with return code 1
[2023-07-26T08:24:40.650+0000] {taskinstance.py:2651} INFO - 0 downstream tasks scheduled from follow-on schedule check
